Workbook

Sheet main_001_analysis_dataset
A1: run_id | B1: experiment_id | C1: task_id | D1: workflow_type | E1: timestamp | F1: prompt | G1: output | H1: answer | I1: execution_summary | J1: confidence | K1: quality_score | L1: score | M1: duration_sec | N1: token_estimate | O1: success | P1: notes | Q1: reviewer_version | R1: real_task_id | S1: category | T1: difficulty | U1: expected_output
A2: 1780574892946 | B2: main_001 | C2: 1 | D2: basic_agent | E2: 46177.631 | F2: Compare OpenAI Gemini and Claude for enterprise workflow automation | G2: { "task_id": "1", "answer": "OpenAI (GPT-4o) excels in ecosystem integration and multimodal agentic capabilities via Assistants API; Google Gemini (1.5 Pro) offers massive 2M token context windows for deep document analysis and seamless integration with Google Workspace; Anthropic (Claude 3.5 Sonnet) leads in coding proficiency, nuanced instruction following, and safety-aligned enterprise reasoning.", "execution_summary": "Evaluated the three models based on core enterprise criteria: context handling, ecosystem interoperability, and reasoning performance. OpenAI is prioritized for broad agent orchestration, Gemini for long-context data ingestion, and Claude for high-stakes technical and creative task execution.", "confidence": 0.95 } | H2: OpenAI (GPT-4o) excels in ecosystem integration and multimodal agentic capabilities via Assistants API; Google Gemini (1.5 Pro) offers massive 2M token context windows for deep document analysis and seamless integration with Google Workspace; Anthropic (Claude 3.5 Sonnet) leads in coding proficiency, nuanced instruction following, and safety-aligned enterprise reasoning. | I2: Evaluated the three models based on core enterprise criteria: context handling, ecosystem interoperability, and reasoning performance. OpenAI is prioritized for broad agent orchestration, Gemini for long-context data ingestion, and Claude for high-stakes technical and creative task execution. | J2: 0.95 | L2: 0 | M2: 0 | N2: 0 | O2: TRUE | P2: main_001_basic_agent | R2: 1 | S2: =VLOOKUP(main_001_90runs__2[[#This Row],[prompt]],tasks!B:E,2,FALSE) -> Knowledge | T2: =VLOOKUP(main_001_90runs__2[[#This Row],[prompt]],tasks!B:E,3,FALSE) -> easy | U2: =VLOOKUP(main_001_90runs__2[[#This Row],[prompt]],tasks!B:E,4,FALSE) -> Structured comparison
A3: 1780574903737 | B3: main_001 | C3: 1 | D3: planner_executor | E3: 46177.631 | F3: Compare OpenAI Gemini and Claude for enterprise workflow automation | G3: { "task_id": "1", "answer": "The enterprise landscape for LLMs is segmented by architectural strengths: OpenAI (GPT-4o) excels in broad ecosystem integration through the Assistants API and Azure, making it the top choice for general-purpose automation. Google (Gemini 1.5 Pro) dominates data-heavy workflows due to its massive 2M-token context window and native Google Workspace integration, perfect for long-document analysis and RAG. Anthropic (Claude 3.5 Sonnet) leads in autonomous agentic workflows, utilizing its Model Context Protocol (MCP) and superior coding/reasoning capabilities for complex, multi-step programmatic execution.", "execution_summary": "Evaluated the three models across defined enterprise criteria. OpenAI offers the most mature API/infrastructure stack. Gemini provides unmatched utility for large-scale enterprise data processing. Claude offers the most reliable, precise output for complex, logic-driven agentic tasks. A recommendation framework suggests: Use GPT-4o for broad-scale integration, Gemini for large-context knowledge retrieval, and Claude for high-stakes reasoning/autonomous task execution.", "confidence": 0.95 } | H3: The enterprise landscape for LLMs is segmented by architectural strengths: OpenAI (GPT-4o) excels in broad ecosystem integration through the Assistants API and Azure, making it the top choice for general-purpose automation. Google (Gemini 1.5 Pro) dominates data-heavy workflows due to its massive 2M-token context window and native Google Workspace integration, perfect for long-document analysis and RAG. Anthropic (Claude 3.5 Sonnet) leads in autonomous agentic workflows, utilizing its Model Context Protocol (MCP) and superior coding/reasoning capabilities for complex, multi-step programmatic execution. | I3: Evaluated the three models across defined enterprise criteria. OpenAI offers the most mature API/infrastructure stack. Gemini provides unmatched utility for large-scale enterprise data processing. Claude offers the most reliable, precise output for complex, logic-driven agentic tasks. A recommendation framework suggests: Use GPT-4o for broad-scale integration, Gemini for large-context knowledge retrieval, and Claude for high-stakes reasoning/autonomous task execution. | J3: 0.95 | L3: 0 | M3: 0 | N3: 0 | O3: TRUE | P3: main_001_planner_executor | R3: 2 | S3: =VLOOKUP(main_001_90runs__2[[#This Row],[prompt]],tasks!B:E,2,FALSE) -> Knowledge | T3: =VLOOKUP(main_001_90runs__2[[#This Row],[prompt]],tasks!B:E,3,FALSE) -> easy | U3: =VLOOKUP(main_001_90runs__2[[#This Row],[prompt]],tasks!B:E,4,FALSE) -> Structured comparison
A4: 1780574915175 | B4: main_001 | C4: 1 | D4: planner_executor_reviewer | E4: 46177.631 | F4: Compare OpenAI Gemini and Claude for enterprise workflow automation | G4: { "task_id": "1", "quality_score": 0.95, "review_notes": "The evaluation is highly accurate and synthesizes the current market positioning of the three models effectively. It correctly identifies the primary value propositions (Azure ecosystem for GPT-4o, long-context for Gemini, and agentic UI/reasoning for Claude). The reasoning is sound, though the 'completeness' could be marginally improved by mentioning enterprise-specific constraints like data privacy/SOC2 compliance or model deployment options (e.g., Bedrock vs. Vertex vs. OpenAI API), which are critical for enterprise decision-making.", "final_answer": "The comparison of GPT-4o, Gemini 1.5 Pro, and Claude 3.5 Sonnet for enterprise workflow automation reveals distinct specializations: GPT-4o excels in ecosystem integration (Azure) and versatile agentic tool-use; Gemini 1.5 Pro dominates in high-volume, long-context data analysis; and Claude 3.5 Sonnet leads in complex reasoning, coding, and direct UI interaction ('Computer Use').", "confidence": 0.98 } | H4: The comparison of GPT-4o, Gemini 1.5 Pro, and Claude 3.5 Sonnet for enterprise workflow automation reveals distinct specializations: GPT-4o excels in ecosystem integration (Azure) and versatile agentic tool-use; Gemini 1.5 Pro dominates in high-volume, long-context data analysis; and Claude 3.5 Sonnet leads in complex reasoning, coding, and direct UI interaction ('Computer Use'). | I4: The evaluation is highly accurate and synthesizes the current market positioning of the three models effectively. It correctly identifies the primary value propositions (Azure ecosystem for GPT-4o, long-context for Gemini, and agentic UI/reasoning for Claude). The reasoning is sound, though the 'completeness' could be marginally improved by mentioning enterprise-specific constraints like data privacy/SOC2 compliance or model deployment options (e.g., Bedrock vs. Vertex vs. OpenAI API), which are critical for enterprise decision-making. | J4: 0.98 | K4: 0.95 | L4: 0 | M4: 0 | N4: 0 | O4: TRUE | P4: main_001_planner_executor_reviewer | Q4: strict_v1 | R4: 3 | S4: =VLOOKUP(main_001_90runs__2[[#This Row],[prompt]],tasks!B:E,2,FALSE) -> Knowledge | T4: =VLOOKUP(main_001_90runs__2[[#This Row],[prompt]],tasks!B:E,3,FALSE) -> easy | U4: =VLOOKUP(main_001_90runs__2[[#This Row],[prompt]],tasks!B:E,4,FALSE) -> Structured comparison
A5: 1780575855817 | B5: main_001 | C5: 1 | D5: basic_agent | E5: 46177.642 | F5: Explain the difference between TCP and UDP | G5: { "task_id": "1", "answer": "TCP (Transmission Control Protocol) is a connection-oriented protocol that ensures reliable, ordered, and error-checked delivery of data packets, making it ideal for web browsing and email. UDP (User Datagram Protocol) is a connectionless, 'best-effort' protocol that prioritizes speed and low latency over reliability, making it suitable for real-time streaming, online gaming, and VoIP.", "execution_summary": "Provided a concise comparison highlighting the key differences in reliability, connection status, and typical use cases between TCP and UDP.", "confidence": 1.0 } | H5: TCP (Transmission Control Protocol) is a connection-oriented protocol that ensures reliable, ordered, and error-checked delivery of data packets, making it ideal for web browsing and email. UDP (User Datagram Protocol) is a connectionless, 'best-effort' protocol that prioritizes speed and low latency over reliability, making it suitable for real-time streaming, online gaming, and VoIP. | I5: Provided a concise comparison highlighting the key differences in reliability, connection status, and typical use cases between TCP and UDP. | J5: 1 | L5: 0 | M5: 0 | N5: 0 | O5: TRUE | P5: main_001_basic_agent | R5: 4 | S5: =VLOOKUP(main_001_90runs__2[[#This Row],[prompt]],tasks!B:E,2,FALSE) -> Knowledge | T5: =VLOOKUP(main_001_90runs__2[[#This Row],[prompt]],tasks!B:E,3,FALSE) -> easy | U5: =VLOOKUP(main_001_90runs__2[[#This Row],[prompt]],tasks!B:E,4,FALSE) -> Technical explanation
A6: 1780575867997 | B6: main_001 | C6: 1 | D6: planner_executor | E6: 46177.642 | F6: Explain the difference between TCP and UDP | G6: { "task_id": "1", "answer": "TCP (Transmission Control Protocol) is a connection-oriented, reliable protocol that ensures data integrity through error checking, packet sequencing, and retransmission of lost data. UDP (User Datagram Protocol) is a connectionless, 'best-effort' protocol that prioritizes speed and low latency over reliability, lacking built-in error recovery or sequencing. Key differences: TCP is reliable with ordered data delivery but carries higher latency and header overhead (20 bytes); UDP is faster with lower overhead (8 bytes) but offers no guarantees on delivery or order. TCP is ideal for applications requiring precision, like web browsing (HTTP), email (SMTP), and file transfers (FTP). UDP is preferred for real-time applications where speed is critical and minor data loss is acceptable, such as live video streaming, VoIP, and online gaming.", "execution_summary": "I have defined both protocols, compared them based on reliability, order, speed, and overhead, identified common use cases, and summarized the trade-offs regarding network requirements.", "confidence": 1.0 } | H6: TCP (Transmission Control Protocol) is a connection-oriented, reliable protocol that ensures data integrity through error checking, packet sequencing, and retransmission of lost data. UDP (User Datagram Protocol) is a connectionless, 'best-effort' protocol that prioritizes speed and low latency over reliability, lacking built-in error recovery or sequencing. Key differences: TCP is reliable with ordered data delivery but carries higher latency and header overhead (20 bytes); UDP is faster with lower overhead (8 bytes) but offers no guarantees on delivery or order. TCP is ideal for applications requiring precision, like web browsing (HTTP), email (SMTP), and file transfers (FTP). UDP is preferred for real-time applications where speed is critical and minor data loss is acceptable, such as live video streaming, VoIP, and online gaming. | I6: I have defined both protocols, compared them based on reliability, order, speed, and overhead, identified common use cases, and summarized the trade-offs regarding network requirements. | J6: 1 | L6: 0 | M6: 0 | N6: 0 | O6: TRUE | P6: main_001_planner_executor | R6: 5 | S6: =VLOOKUP(main_001_90runs__2[[#This Row],[prompt]],tasks!B:E,2,FALSE) -> Knowledge | T6: =VLOOKUP(main_001_90runs__2[[#This Row],[prompt]],tasks!B:E,3,FALSE) -> easy | U6: =VLOOKUP(main_001_90runs__2[[#This Row],[prompt]],tasks!B:E,4,FALSE) -> Technical explanation
A7: 1780575879320 | B7: main_001 | C7: 1 | D7: planner_executor_reviewer | E7: 46177.642 | F7: Explain the difference between TCP and UDP | G7: { "task_id": "1", "quality_score": 1.0, "review_notes": "The response is academically rigorous and precise. It accurately characterizes the technical distinctions between TCP and UDP, correctly identifies the fundamental trade-off (reliability vs. latency), and provides appropriate, illustrative examples for both protocols. The definitions of 'connection-oriented' versus 'connectionless' are correctly contextualized.", "final_answer": "TCP (Transmission Control Protocol) is a connection-oriented, reliable protocol that ensures data delivery through acknowledgments, retransmissions, and flow control, guaranteeing packets arrive in the correct order. In contrast, UDP (User Datagram Protocol) is a connectionless, 'best-effort' protocol that prioritizes speed and low overhead by sending data packets (datagrams) without verifying receipt, delivery order, or flow control. TCP is essential for applications requiring high integrity, such as file transfers (FTP), email (SMTP), and web browsing (HTTP/HTTPS), while UDP is ideal for time-sensitive applications where speed is prioritized over minor data loss, such as live video streaming, VoIP, and online gaming. The fundamental trade-off is between reliability (TCP) and performance/latency (UDP).", "confidence": 1.0 } | H7: TCP (Transmission Control Protocol) is a connection-oriented, reliable protocol that ensures data delivery through acknowledgments, retransmissions, and flow control, guaranteeing packets arrive in the correct order. In contrast, UDP (User Datagram Protocol) is a connectionless, 'best-effort' protocol that prioritizes speed and low overhead by sending data packets (datagrams) without verifying receipt, delivery order, or flow control. TCP is essential for applications requiring high integrity, such as file transfers (FTP), email (SMTP), and web browsing (HTTP/HTTPS), while UDP is ideal for time-sensitive applications where speed is prioritized over minor data loss, such as live video streaming, VoIP, and online gaming. The fundamental trade-off is between reliability (TCP) and performance/latency (UDP). | I7: The response is academically rigorous and precise. It accurately characterizes the technical distinctions between TCP and UDP, correctly identifies the fundamental trade-off (reliability vs. latency), and provides appropriate, illustrative examples for both protocols. The definitions of 'connection-oriented' versus 'connectionless' are correctly contextualized. | J7: 1 | K7: 1 | L7: 0 | M7: 0 | N7: 0 | O7: TRUE | P7: main_001_planner_executor_reviewer | Q7: strict_v1 | R7: 6 | S7: =VLOOKUP(main_001_90runs__2[[#This Row],[prompt]],tasks!B:E,2,FALSE) -> Knowledge | T7: =VLOOKUP(main_001_90runs__2[[#This Row],[prompt]],tasks!B:E,3,FALSE) -> easy | U7: =VLOOKUP(main_001_90runs__2[[#This Row],[prompt]],tasks!B:E,4,FALSE) -> Technical explanation
A8: 1780576994343 | B8: main_001 | C8: 1 | D8: basic_agent | E8: 46177.655 | F8: Compare REST APIs and GraphQL APIs | G8: { "task_id": "1", "answer": "REST APIs are resource-based, using standard HTTP methods and multiple endpoints to access data, often leading to over-fetching or under-fetching. GraphQL is a query language for APIs that uses a single endpoint, allowing clients to request exactly the data they need, which improves efficiency and provides a strongly-typed schema.", "execution_summary": "Compared REST and GraphQL based on architecture, data fetching efficiency, and schema definition.", "confidence": 1.0 } | H8: REST APIs are resource-based, using standard HTTP methods and multiple endpoints to access data, often leading to over-fetching or under-fetching. GraphQL is a query language for APIs that uses a single endpoint, allowing clients to request exactly the data they need, which improves efficiency and provides a strongly-typed schema. | I8: Compared REST and GraphQL based on architecture, data fetching efficiency, and schema definition. | J8: 1 | L8: 0 | M8: 0 | N8: 0 | O8: TRUE | P8: main_001_basic_agent | R8: 7 | S8: =VLOOKUP(main_001_90runs__2[[#This Row],[prompt]],tasks!B:E,2,FALSE) -> Knowledge | T8: =VLOOKUP(main_001_90runs__2[[#This Row],[prompt]],tasks!B:E,3,FALSE) -> easy | U8: =VLOOKUP(main_001_90runs__2[[#This Row],[prompt]],tasks!B:E,4,FALSE) -> Comparison report
A9: 1780577003965 | B9: main_001 | C9: 1 | D9: planner_executor | E9: 46177.655 | F9: Compare REST APIs and GraphQL APIs | G9: { "task_id": "1", "answer": "REST is a resource-based architectural style using multiple endpoints (e.g., /users, /posts) and fixed data structures, where the server defines the payload. GraphQL is a query-based language operating via a single endpoint, allowing clients to request exactly the data they need through a schema-defined type system.\n\nKey differences include:\n- Data Fetching: REST often suffers from over-fetching (getting more data than needed) or under-fetching (requiring multiple requests), while GraphQL solves this with precise data selection.\n- Versioning: REST typically uses URI versioning (v1/v2), whereas GraphQL promotes schema evolution with deprecated fields.\n- Performance: REST benefits from standard HTTP caching mechanisms. GraphQL requires more complex caching strategies due to its single-endpoint POST nature.\n\nPros/Cons:\n- REST Pros: Simple to implement, mature tooling, excellent cacheability. Cons: Inflexible payloads, potential request chaining.\n- GraphQL Pros: High flexibility, strong typing, reduces network traffic. Cons: Complexity in server setup, caching difficulty, potential for malicious deep queries.\n\nDecision Framework:\n- Use REST if: You need simple, resource-oriented APIs, rely heavily on HTTP caching, or are building public APIs with low complexity.\n- Use GraphQL if: You have complex data graphs with relationships, operate in bandwidth-constrained environments (mobile), or need to aggregate data from multiple microservices into one interface.", "execution_summary": "Executed all steps: defined architectures for both APIs, compared key operational metrics, summarized pros/cons, and provided a practical selection framework.", "confidence": 1.0 } | H9: REST is a resource-based architectural style using multiple endpoints (e.g., /users, /posts) and fixed data structures, where the server defines the payload. GraphQL is a query-based language operating via a single endpoint, allowing clients to request exactly the data they need through a schema-defined type system. Key differences include: - Data Fetching: REST often suffers from over-fetching (getting more data than needed) or under-fetching (requiring multiple requests), while GraphQL solves this with precise data selection. - Versioning: REST typically uses URI versioning (v1/v2), whereas GraphQL promotes schema evolution with deprecated fields. - Performance: REST benefits from standard HTTP caching mechanisms. GraphQL requires more complex caching strategies due to its single-endpoint POST nature. Pros/Cons: - REST Pros: Simple to implement, mature tooling, excellent cacheability. Cons: Inflexible payloads, potential request chaining. - GraphQL Pros: High flexibility, strong typing, reduces network traffic. Cons: Complexity in server setup, caching difficulty, potential for malicious deep queries. Decision Framework: - Use REST if: You need simple, resource-oriented APIs, rely heavily on HTTP caching, or are building public APIs with low complexity. - Use GraphQL if: You have complex data graphs with relationships, operate in bandwidth-constrained environments (mobile), or need to aggregate data from multiple microservices into one interface. | I9: Executed all steps: defined architectures for both APIs, compared key operational metrics, summarized pros/cons, and provided a practical selection framework. | J9: 1 | L9: 0 | M9: 0 | N9: 0 | O9: TRUE | P9: main_001_planner_executor | R9: 8 | S9: =VLOOKUP(main_001_90runs__2[[#This Row],[prompt]],tasks!B:E,2,FALSE) -> Knowledge | T9: =VLOOKUP(main_001_90runs__2[[#This Row],[prompt]],tasks!B:E,3,FALSE) -> easy | U9: =VLOOKUP(main_001_90runs__2[[#This Row],[prompt]],tasks!B:E,4,FALSE) -> Comparison report
A10: 1780577017923 | B10: main_001 | C10: 1 | D10: planner_executor_reviewer | E10: 46177.655 | F10: Compare REST APIs and GraphQL APIs | G10: { "task_id": "1", "quality_score": 0.95, "review_notes": "The response is technically accurate, well-structured, and demonstrates a deep understanding of the comparative nuances between REST and GraphQL. The inclusion of critical trade-offs such as caching mechanisms and versioning strategies is excellent. The only minor area for improvement would be to acknowledge that REST can technically support partial responses (e.g., field selection) via query parameters, though GraphQL provides this natively as a first-class feature. Otherwise, the analysis is exemplary.", "final_answer": "REST and GraphQL represent fundamentally different approaches to API design: \n\n1. Architecture: REST is resource-based, where each URI represents a specific entity and operations are performed via HTTP methods (GET, POST, PUT, DELETE). GraphQL is a query language and runtime that acts as a schema-based layer, allowing clients to interact with a single endpoint to fetch exactly what they need.\n\n2. Data Fetching: REST often suffers from over-fetching (getting more data than needed) or under-fetching (requiring multiple round trips), whereas GraphQL allows clients to define the shape of the response, enabling precise data retrieval in a single request.\n\n3. Versioning/Schema: REST versioning is typically handled via URI paths (e.g., /v1/) or headers, which can lead to maintenance overhead. GraphQL uses a strongly typed schema; fields can be deprecated rather than versioned, providing a smoother evolution path.\n\n4. Performance/Caching: REST excels at HTTP-level caching because it leverages standard HTTP semantics. GraphQL is more complex to cache because it usually operates over POST requests and requires application-level caching or specialized tools (like Apollo Client) to manage data persistence.\n\n5. Use Cases: REST is ideal for public APIs where standard HTTP caching is critical and simple resource manipulation is required. GraphQL is ideal for complex, interconnected data models, mobile applications with bandwidth constraints, and fast-paced frontend development.", "confidence": 1.0 } | H10: REST and GraphQL represent fundamentally different approaches to API design: 1. Architecture: REST is resource-based, where each URI represents a specific entity and operations are performed via HTTP methods (GET, POST, PUT, DELETE). GraphQL is a query language and runtime that acts as a schema-based layer, allowing clients to interact with a single endpoint to fetch exactly what they need. 2. Data Fetching: REST often suffers from over-fetching (getting more data than needed) or under-fetching (requiring multiple round trips), whereas GraphQL allows clients to define the shape of the response, enabling precise data retrieval in a single request. 3. Versioning/Schema: REST versioning is typically handled via URI paths (e.g., /v1/) or headers, which can lead to maintenance overhead. GraphQL uses a strongly typed schema; fields can be deprecated rather than versioned, providing a smoother evolution path. 4. Performance/Caching: REST excels at HTTP-level caching because it leverages standard HTTP semantics. GraphQL is more complex to cache because it usually operates over POST requests and requires application-level caching or specialized tools (like Apollo Client) to manage data persistence. 5. Use Cases: REST is ideal for public APIs where standard HTTP caching is critical and simple resource manipulation is required. GraphQL is ideal for complex, interconnected data models, mobile applications with bandwidth constraints, and fast-paced frontend development. | I10: The response is technically accurate, well-structured, and demonstrates a deep understanding of the comparative nuances between REST and GraphQL. The inclusion of critical trade-offs such as caching mechanisms and versioning strategies is excellent. The only minor area for improvement would be to acknowledge that REST can technically support partial responses (e.g., field selection) via query parameters, though GraphQL provides this natively as a first-class feature. Otherwise, the analysis is exemplary. | J10: 1 | K10: 0.95 | L10: 0 | M10: 0 | N10: 0 | O10: TRUE | P10: main_001_planner_executor_reviewer | Q10: strict_v1 | R10: 9 | S10: =VLOOKUP(main_001_90runs__2[[#This Row],[prompt]],tasks!B:E,2,FALSE) -> Knowledge | T10: =VLOOKUP(main_001_90runs__2[[#This Row],[prompt]],tasks!B:E,3,FALSE) -> easy | U10: =VLOOKUP(main_001_90runs__2[[#This Row],[prompt]],tasks!B:E,4,FALSE) -> Comparison report
A11: 1780578566594 | B11: main_001 | C11: 1 | D11: basic_agent | E11: 46177.673 | F11: Summarize recent trends in agentic AI automation | G11: { "task_id": "1", "answer": "Recent trends in agentic AI involve a transition from passive chatbots to autonomous systems capable of multi-step reasoning, tool use, and long-term planning. Key developments include the rise of 'agent-to-agent' collaboration, improved error correction through self-reflection loops, and a shift toward local, domain-specific agent frameworks that prioritize security and task-oriented accuracy over general-purpose conversation.", "execution_summary": "Synthesized market trends regarding agentic workflows, multi-step reasoning, and architectural shifts toward domain-specific autonomy.", "confidence": 0.95 } | H11: Recent trends in agentic AI involve a transition from passive chatbots to autonomous systems capable of multi-step reasoning, tool use, and long-term planning. Key developments include the rise of 'agent-to-agent' collaboration, improved error correction through self-reflection loops, and a shift toward local, domain-specific agent frameworks that prioritize security and task-oriented accuracy over general-purpose conversation. | I11: Synthesized market trends regarding agentic workflows, multi-step reasoning, and architectural shifts toward domain-specific autonomy. | J11: 0.95 | L11: 0 | M11: 0 | N11: 0 | O11: TRUE | P11: main_001_basic_agent | R11: 10 | S11: =VLOOKUP(main_001_90runs__2[[#This Row],[prompt]],tasks!B:E,2,FALSE) -> Knowledge | T11: =VLOOKUP(main_001_90runs__2[[#This Row],[prompt]],tasks!B:E,3,FALSE) -> medium | U11: =VLOOKUP(main_001_90runs__2[[#This Row],[prompt]],tasks!B:E,4,FALSE) -> Executive summary
A12: 1780578577218 | B12: main_001 | C12: 1 | D12: planner_executor | E12: 46177.673 | F12: Summarize recent trends in agentic AI automation | G12: { "task_id": "1", "answer": "Recent trends in agentic AI signify a pivotal shift from passive chatbot interfaces to proactive, goal-oriented task execution. This evolution is characterized by three core pillars: 1) Technical breakthroughs in multi-agent orchestration and reasoning frameworks (e.g., Chain-of-Thought, ReAct, and self-correction loops) that enable agents to handle complex, non-linear workflows. 2) Operational integration, where AI agents act as autonomous 'employees' within enterprise ecosystems, executing multi-step tasks across SaaS applications rather than merely generating text. 3) A heightened focus on safety and governance, specifically 'guardrailing' agent autonomy through human-in-the-loop systems and robust evaluation frameworks to mitigate hallucination and unauthorized actions. The industry is rapidly moving toward autonomous systems capable of reasoning, planning, and executing end-to-end business outcomes.", "execution_summary": "Executed a research-driven synthesis of agentic AI trends by analyzing developments from late 2023 to present. Findings were categorized into technical advancements, operational workflows, and governance, resulting in a concise summary of the shift from conversational AI to autonomous execution.", "confidence": 0.95 } | H12: Recent trends in agentic AI signify a pivotal shift from passive chatbot interfaces to proactive, goal-oriented task execution. This evolution is characterized by three core pillars: 1) Technical breakthroughs in multi-agent orchestration and reasoning frameworks (e.g., Chain-of-Thought, ReAct, and self-correction loops) that enable agents to handle complex, non-linear workflows. 2) Operational integration, where AI agents act as autonomous 'employees' within enterprise ecosystems, executing multi-step tasks across SaaS applications rather than merely generating text. 3) A heightened focus on safety and governance, specifically 'guardrailing' agent autonomy through human-in-the-loop systems and robust evaluation frameworks to mitigate hallucination and unauthorized actions. The industry is rapidly moving toward autonomous systems capable of reasoning, planning, and executing end-to-end business outcomes. | I12: Executed a research-driven synthesis of agentic AI trends by analyzing developments from late 2023 to present. Findings were categorized into technical advancements, operational workflows, and governance, resulting in a concise summary of the shift from conversational AI to autonomous execution. | J12: 0.95 | L12: 0 | M12: 0 | N12: 0 | O12: TRUE | P12: main_001_planner_executor | R12: 11 | S12: =VLOOKUP(main_001_90runs__2[[#This Row],[prompt]],tasks!B:E,2,FALSE) -> Knowledge | T12: =VLOOKUP(main_001_90runs__2[[#This Row],[prompt]],tasks!B:E,3,FALSE) -> medium | U12: =VLOOKUP(main_001_90runs__2[[#This Row],[prompt]],tasks!B:E,4,FALSE) -> Executive summary
A13: 1780578589961 | B13: main_001 | C13: 1 | D13: planner_executor_reviewer | E13: 46177.673 | F13: Summarize recent trends in agentic AI automation | G13: { "task_id": "1", "quality_score": 0.95, "review_notes": "The execution is excellent, providing a concise yet comprehensive overview of the current agentic AI landscape. It accurately identifies the pivotal shift from single-task execution to multi-agent orchestration. The taxonomy of trends (Frameworks, Tool-Use, Memory, HITL, Reasoning) is logically structured and reflects the current state of industry discourse. The reasoning is sound, synthesizing technical advancements without unnecessary jargon. The summary would benefit slightly from explicitly mentioning the role of 'Small Language Models' (SLMs) in efficient agentic deployment, but it remains highly competent as is.", "final_answer": "Recent trends in agentic AI are characterized by a shift from single-task models to autonomous, multi-agent ecosystems. Key advancements include: 1) Multi-Agent Frameworks: Orchestration layers (e.g., AutoGen, CrewAI) allow specialized agents to collaborate, improving complex task decomposition. 2) Tool-Use Evolution: Agents have transitioned from simple API calls to dynamic environments where they can execute code, browse the web, and manage software interfaces iteratively. 3) Memory Integration: The adoption of long-term memory via vector databases enables agents to retain context across sessions, enhancing personalization and consistency. 4) Human-in-the-Loop (HITL): Workflow design is increasingly prioritizing 'controlled autonomy,' where humans provide strategic oversight and verification in iterative cycles. 5) Reasoning Capabilities: Models are leveraging advanced chain-of-thought and self-correction mechanisms to reduce hallucination rates.", "confidence": 1.0 } | H13: Recent trends in agentic AI are characterized by a shift from single-task models to autonomous, multi-agent ecosystems. Key advancements include: 1) Multi-Agent Frameworks: Orchestration layers (e.g., AutoGen, CrewAI) allow specialized agents to collaborate, improving complex task decomposition. 2) Tool-Use Evolution: Agents have transitioned from simple API calls to dynamic environments where they can execute code, browse the web, and manage software interfaces iteratively. 3) Memory Integration: The adoption of long-term memory via vector databases enables agents to retain context across sessions, enhancing personalization and consistency. 4) Human-in-the-Loop (HITL): Workflow design is increasingly prioritizing 'controlled autonomy,' where humans provide strategic oversight and verification in iterative cycles. 5) Reasoning Capabilities: Models are leveraging advanced chain-of-thought and self-correction mechanisms to reduce hallucination rates. | I13: The execution is excellent, providing a concise yet comprehensive overview of the current agentic AI landscape. It accurately identifies the pivotal shift from single-task execution to multi-agent orchestration. The taxonomy of trends (Frameworks, Tool-Use, Memory, HITL, Reasoning) is logically structured and reflects the current state of industry discourse. The reasoning is sound, synthesizing technical advancements without unnecessary jargon. The summary would benefit slightly from explicitly mentioning the role of 'Small Language Models' (SLMs) in efficient agentic deployment, but it remains highly competent as is. | J13: 1 | K13: 0.95 | L13: 0 | M13: 0 | N13: 0 | O13: TRUE | P13: main_001_planner_executor_reviewer | Q13: strict_v1 | R13: 12 | S13: =VLOOKUP(main_001_90runs__2[[#This Row],[prompt]],tasks!B:E,2,FALSE) -> Knowledge | T13: =VLOOKUP(main_001_90runs__2[[#This Row],[prompt]],tasks!B:E,3,FALSE) -> medium | U13: =VLOOKUP(main_001_90runs__2[[#This Row],[prompt]],tasks!B:E,4,FALSE) -> Executive summary
A14: 1780578618719 | B14: main_001 | C14: 1 | D14: basic_agent | E14: 46177.674 | F14: Identify risks of using LLM agents in business processes | G14: { "task_id": "1", "answer": "The key risks include: 1) Data Privacy/Security (leakage of proprietary data); 2) Hallucinations (inaccurate or fabricated output); 3) Bias and Unfairness (propagation of prejudiced training data); 4) Lack of Explainability (the 'black box' problem); 5) Cost/Performance volatility; and 6) Security vulnerabilities (prompt injection and indirect prompt injection attacks).", "execution_summary": "Identified primary categories of risk associated with deploying LLM agents in enterprise environments.", "confidence": 1.0 } | H14: The key risks include: 1) Data Privacy/Security (leakage of proprietary data); 2) Hallucinations (inaccurate or fabricated output); 3) Bias and Unfairness (propagation of prejudiced training data); 4) Lack of Explainability (the 'black box' problem); 5) Cost/Performance volatility; and 6) Security vulnerabilities (prompt injection and indirect prompt injection attacks). | I14: Identified primary categories of risk associated with deploying LLM agents in enterprise environments. | J14: 1 | L14: 0 | M14: 0 | N14: 0 | O14: TRUE | P14: main_001_basic_agent | R14: 13 | S14: =VLOOKUP(main_001_90runs__2[[#This Row],[prompt]],tasks!B:E,2,FALSE) -> Knowledge | T14: =VLOOKUP(main_001_90runs__2[[#This Row],[prompt]],tasks!B:E,3,FALSE) -> medium | U14: =VLOOKUP(main_001_90runs__2[[#This Row],[prompt]],tasks!B:E,4,FALSE) -> Risk assessment
A15: 1780578629992 | B15: main_001 | C15: 1 | D15: planner_executor | E15: 46177.674 | F15: Identify risks of using LLM agents in business processes | G15: { "task_id": "1", "answer": "The deployment of LLM agents in business necessitates a multi-dimensional risk framework. Technical risks include non-deterministic outputs (hallucinations) and malicious manipulation (prompt injection). Operational risks involve high latency and reliability gaps in complex workflows. Data-related risks center on PI leakage and non-compliance with regulations (GDPR/CCPA). Ethical/legal risks encompass bias, IP infringement, and lack of accountability. Impact analysis shows these risks can lead to service disruption, financial loss, and severe brand damage. Mitigation requires a defense-in-depth approach: implementing guardrails (e.g., NeMo Guardrails), strict access control, rigorous human-in-the-loop validation, and continuous adversarial testing.", "execution_summary": "I executed the plan by mapping LLM integration risks across four key dimensions: technical, operational, data-related, and ethical/legal. I assessed the systemic impact on business continuity and established a mitigation framework including automated filtering, oversight protocols, and compliance auditing to produce this final risk assessment.", "confidence": 1.0 } | H15: The deployment of LLM agents in business necessitates a multi-dimensional risk framework. Technical risks include non-deterministic outputs (hallucinations) and malicious manipulation (prompt injection). Operational risks involve high latency and reliability gaps in complex workflows. Data-related risks center on PI leakage and non-compliance with regulations (GDPR/CCPA). Ethical/legal risks encompass bias, IP infringement, and lack of accountability. Impact analysis shows these risks can lead to service disruption, financial loss, and severe brand damage. Mitigation requires a defense-in-depth approach: implementing guardrails (e.g., NeMo Guardrails), strict access control, rigorous human-in-the-loop validation, and continuous adversarial testing. | I15: I executed the plan by mapping LLM integration risks across four key dimensions: technical, operational, data-related, and ethical/legal. I assessed the systemic impact on business continuity and established a mitigation framework including automated filtering, oversight protocols, and compliance auditing to produce this final risk assessment. | J15: 1 | L15: 0 | M15: 0 | N15: 0 | O15: TRUE | P15: main_001_planner_executor | R15: 14 | S15: =VLOOKUP(main_001_90runs__2[[#This Row],[prompt]],tasks!B:E,2,FALSE) -> Knowledge | T15: =VLOOKUP(main_001_90runs__2[[#This Row],[prompt]],tasks!B:E,3,FALSE) -> medium | U15: =VLOOKUP(main_001_90runs__2[[#This Row],[prompt]],tasks!B:E,4,FALSE) -> Risk assessment
A16: 1780578642455 | B16: main_001 | C16: 1 | D16: planner_executor_reviewer | E16: 46177.674 | F16: Identify risks of using LLM agents in business processes | G16: { "task_id": "1", "quality_score": 0.95, "review_notes": "The response is highly accurate, well-structured, and professional. It correctly identifies the core risk domains associated with LLM integration. The reasoning is sound, and the categorization provides a logical framework for business analysis. The only minor improvement would be to include 'Systemic/Dependency' risks (e.g., model drift, API outages, or vendor lock-in) to reach absolute completeness, but the current response is excellent for a high-level assessment.", "final_answer": "The risks associated with integrating LLM agents into business operations are categorized into four primary domains: 1) Security: Risks include prompt injection attacks, unauthorized access to sensitive data, and data leakage during model training or inference. 2) Operational: Risks involve hallucinations (fictitious outputs), non-deterministic responses making systems hard to debug, and the dangers of bypassing human-in-the-loop oversight. 3) Legal/Compliance: Risks cover potential copyright infringement, failure to comply with data privacy regulations (GDPR/CCPA) due to data retention policies, and challenges in maintaining audit trails for automated decisions. 4) Reputational: Risks encompass the propagation of algorithmic bias, the generation of offensive or inappropriate content, and the subsequent erosion of customer trust if agents perform poorly or unpredictably.", "confidence": 1.0 } | H16: The risks associated with integrating LLM agents into business operations are categorized into four primary domains: 1) Security: Risks include prompt injection attacks, unauthorized access to sensitive data, and data leakage during model training or inference. 2) Operational: Risks involve hallucinations (fictitious outputs), non-deterministic responses making systems hard to debug, and the dangers of bypassing human-in-the-loop oversight. 3) Legal/Compliance: Risks cover potential copyright infringement, failure to comply with data privacy regulations (GDPR/CCPA) due to data retention policies, and challenges in maintaining audit trails for automated decisions. 4) Reputational: Risks encompass the propagation of algorithmic bias, the generation of offensive or inappropriate content, and the subsequent erosion of customer trust if agents perform poorly or unpredictably. | I16: The response is highly accurate, well-structured, and professional. It correctly identifies the core risk domains associated with LLM integration. The reasoning is sound, and the categorization provides a logical framework for business analysis. The only minor improvement would be to include 'Systemic/Dependency' risks (e.g., model drift, API outages, or vendor lock-in) to reach absolute completeness, but the current response is excellent for a high-level assessment. | J16: 1 | K16: 0.95 | L16: 0 | M16: 0 | N16: 0 | O16: TRUE | P16: main_001_planner_executor_reviewer | Q16: strict_v1 | R16: 15 | S16: =VLOOKUP(main_001_90runs__2[[#This Row],[prompt]],tasks!B:E,2,FALSE) -> Knowledge | T16: =VLOOKUP(main_001_90runs__2[[#This Row],[prompt]],tasks!B:E,3,FALSE) -> medium | U16: =VLOOKUP(main_001_90runs__2[[#This Row],[prompt]],tasks!B:E,4,FALSE) -> Risk assessment
A17: 1780592134171 | B17: main_001 | C17: 1 | D17: basic_agent | E17: 46177.83 | F17: Compare vector databases and relational databases | G17: { "task_id": "1", "answer": "Relational databases (RDBMS) organize structured data into predefined tables with rows and columns, utilizing SQL for exact-match queries and ACID compliance. Vector databases are specialized to store, index, and query high-dimensional vector embeddings, enabling similarity searches (e.g., k-NN) in unstructured data like text, images, or audio. While RDBMS excels at transactional integrity and structured relationships, vector databases are designed for semantic understanding and retrieval-augmented generation (RAG) in AI applications.", "execution_summary": "Compared data structures, query paradigms, and primary use cases for both database types.", "confidence": 1.0 } | H17: Relational databases (RDBMS) organize structured data into predefined tables with rows and columns, utilizing SQL for exact-match queries and ACID compliance. Vector databases are specialized to store, index, and query high-dimensional vector embeddings, enabling similarity searches (e.g., k-NN) in unstructured data like text, images, or audio. While RDBMS excels at transactional integrity and structured relationships, vector databases are designed for semantic understanding and retrieval-augmented generation (RAG) in AI applications. | I17: Compared data structures, query paradigms, and primary use cases for both database types. | J17: 1 | L17: 0 | M17: 0 | N17: 0 | O17: TRUE | P17: main_001_basic_agent | R17: 16 | S17: =VLOOKUP(main_001_90runs__2[[#This Row],[prompt]],tasks!B:E,2,FALSE) -> Knowledge | T17: =VLOOKUP(main_001_90runs__2[[#This Row],[prompt]],tasks!B:E,3,FALSE) -> medium | U17: =VLOOKUP(main_001_90runs__2[[#This Row],[prompt]],tasks!B:E,4,FALSE) -> Structured comparison
A18: 1780592144663 | B18: main_001 | C18: 1 | D18: planner_executor | E18: 46177.83 | F18: Compare vector databases and relational databases | G18: { "task_id": "1", "answer": "Relational databases (RDBMS) organize data into strictly typed tables using rows and columns, optimized for structured data and ACID compliance to ensure transactional integrity via SQL. In contrast, vector databases are purpose-built to store and retrieve high-dimensional embeddings—numerical representations of unstructured data like text, images, or audio—using advanced indexing techniques (e.g., HNSW, IVF) to perform approximate nearest-neighbor similarity searches. While RDBMS excels at precise, query-based retrieval and maintaining relationships between entities, vector databases prioritize semantic relevance and contextual searching. RDBMS is the standard for transactional systems (e.g., ERP, CRM), whereas vector databases are foundational for modern AI applications, such as Retrieval-Augmented Generation (RAG) and recommendation engines. They are fundamentally complementary; modern architectures frequently combine them, using the RDBMS for metadata and transactional records and the vector database for managing latent-space knowledge.", "execution_summary": "I have defined the architectures for both database types, analyzed their query mechanisms (ACID/SQL vs. vector similarity), compared performance and data handling, and identified distinct use cases. The synthesis confirms that these technologies serve different roles in modern data stacks, acting as complementary tools rather than direct replacements for one another.", "confidence": 1.0 } | H18: Relational databases (RDBMS) organize data into strictly typed tables using rows and columns, optimized for structured data and ACID compliance to ensure transactional integrity via SQL. In contrast, vector databases are purpose-built to store and retrieve high-dimensional embeddings—numerical representations of unstructured data like text, images, or audio—using advanced indexing techniques (e.g., HNSW, IVF) to perform approximate nearest-neighbor similarity searches. While RDBMS excels at precise, query-based retrieval and maintaining relationships between entities, vector databases prioritize semantic relevance and contextual searching. RDBMS is the standard for transactional systems (e.g., ERP, CRM), whereas vector databases are foundational for modern AI applications, such as Retrieval-Augmented Generation (RAG) and recommendation engines. They are fundamentally complementary; modern architectures frequently combine them, using the RDBMS for metadata and transactional records and the vector database for managing latent-space knowledge. | I18: I have defined the architectures for both database types, analyzed their query mechanisms (ACID/SQL vs. vector similarity), compared performance and data handling, and identified distinct use cases. The synthesis confirms that these technologies serve different roles in modern data stacks, acting as complementary tools rather than direct replacements for one another. | J18: 1 | L18: 0 | M18: 0 | N18: 0 | O18: TRUE | P18: main_001_planner_executor | R18: 17 | S18: =VLOOKUP(main_001_90runs__2[[#This Row],[prompt]],tasks!B:E,2,FALSE) -> Knowledge | T18: =VLOOKUP(main_001_90runs__2[[#This Row],[prompt]],tasks!B:E,3,FALSE) -> medium | U18: =VLOOKUP(main_001_90runs__2[[#This Row],[prompt]],tasks!B:E,4,FALSE) -> Structured comparison
A19: 1780592161109 | B19: main_001 | C19: 1 | D19: planner_executor_reviewer | E19: 46177.831 | F19: Compare vector databases and relational databases | G19: { "task_id": "1", "quality_score": 0.98, "review_notes": "The response is academically rigorous, technically precise, and logically structured. It correctly identifies the fundamental distinction between exact-match relational algebra and similarity-based high-dimensional search. It appropriately notes the convergence of these technologies (e.g., pgvector) and correctly identifies the trade-off between ACID compliance and high-throughput vector retrieval. The summary table is a high-value synthesis tool. The only minor improvement would be a brief mention of the 'curse of dimensionality' as a core technical driver for why specialized vector indices are required over standard relational B-trees.", "final_answer": "Relational Databases (RDBMS) and Vector Databases represent two distinct paradigms for data management, optimized for different data types and retrieval goals.\n\n### 1. Core Architecture and Use Cases\n- **RDBMS:** Built on the relational model (tables/rows/columns) with a focus on transactional integrity. They are designed for structured data where precision is paramount, such as financial transactions, inventory management, and CRUD applications.\n- **Vector Databases:** Designed to store, index, and retrieve high-dimensional vector embeddings. They are built for unstructured data (text, images, audio) transformed into numerical vectors. Primary use cases include RAG (Retrieval-Augmented Generation), semantic search, recommendation systems, and computer vision.\n\n### 2. Data Structure and Query Methods\n- **Structure:** RDBMS handle structured, highly normalized data. Vector databases handle unstructured data represented as dense numerical vectors.\n- **Queries:** RDBMS rely on SQL (Structured Query Language) for exact filtering and relational joins. Vector databases use Approximate Nearest Neighbor (ANN) search to find data points based on semantic proximity (cosine similarity, Euclidean distance) rather than exact matches.\n\n### 3. Performance Trade-offs\n- **Indexing:** RDBMS use B-trees or hash indexes for fast exact lookups. Vector databases utilize ANN algorithms like HNSW (Hierarchical Navigable Small World) or IVF (Inverted File Index) to balance search speed with recall accuracy.\n- **Compliance:** RDBMS prioritize ACID (Atomicity, Consistency, Isolation, Durability) properties. Vector databases often favor eventual consistency and high-throughput retrieval, as many AI applications prioritize speed and semantic relevance over immediate write consistency.\n\n### 4. Hybrid Approaches\nMost modern applications use a hybrid architecture: RDBMS stores metadata, user profiles, and transactional data, while the vector database acts as an 'AI memory layer' for semantic context. Many RDBMS (e.g., PostgreSQL with pgvector) are also adding vector support to minimize infrastructure overhead.\n\n### 5. Summary Table\n| Feature | Relational Database (RDBMS) | Vector Database |\n| :--- | :--- | :--- |\n| **Data Type** | Structured | Unstructured (Embeddings) |\n| **Search Logic** | Exact/Predicate Matching | Semantic/Similarity Search |\n| **Primary Index** | B-trees | ANN (HNSW, IVF) |\n| **Consistency** | Strong (ACID) | Often Eventual |\n| **Best For** | Transactions, Auditing | LLMs, Recommendations, AI |", "confidence": 1.0 } | H19: Relational Databases (RDBMS) and Vector Databases represent two distinct paradigms for data management, optimized for different data types and retrieval goals. ### 1. Core Architecture and Use Cases - **RDBMS:** Built on the relational model (tables/rows/columns) with a focus on transactional integrity. They are designed for structured data where precision is paramount, such as financial transactions, inventory management, and CRUD applications. - **Vector Databases:** Designed to store, index, and retrieve high-dimensional vector embeddings. They are built for unstructured data (text, images, audio) transformed into numerical vectors. Primary use cases include RAG (Retrieval-Augmented Generation), semantic search, recommendation systems, and computer vision. ### 2. Data Structure and Query Methods - **Structure:** RDBMS handle structured, highly normalized data. Vector databases handle unstructured data represented as dense numerical vectors. - **Queries:** RDBMS rely on SQL (Structured Query Language) for exact filtering and relational joins. Vector databases use Approximate Nearest Neighbor (ANN) search to find data points based on semantic proximity (cosine similarity, Euclidean distance) rather than exact matches. ### 3. Performance Trade-offs - **Indexing:** RDBMS use B-trees or hash indexes for fast exact lookups. Vector databases utilize ANN algorithms like HNSW (Hierarchical Navigable Small World) or IVF (Inverted File Index) to balance search speed with recall accuracy. - **Compliance:** RDBMS prioritize ACID (Atomicity, Consistency, Isolation, Durability) properties. Vector databases often favor eventual consistency and high-throughput retrieval, as many AI applications prioritize speed and semantic relevance over immediate write consistency. ### 4. Hybrid Approaches Most modern applications use a hybrid architecture: RDBMS stores metadata, user profiles, and transactional data, while the vector database acts as an 'AI memory layer' for semantic context. Many RDBMS (e.g., PostgreSQL with pgvector) are also adding vector support to minimize infrastructure overhead. ### 5. Summary Table | Feature | Relational Database (RDBMS) | Vector Database | | :--- | :--- | :--- | | **Data Type** | Structured | Unstructured (Embeddings) | | **Search Logic** | Exact/Predicate Matching | Semantic/Similarity Search | | **Primary Index** | B-trees | ANN (HNSW, IVF) | | **Consistency** | Strong (ACID) | Often Eventual | | **Best For** | Transactions, Auditing | LLMs, Recommendations, AI | | I19: The response is academically rigorous, technically precise, and logically structured. It correctly identifies the fundamental distinction between exact-match relational algebra and similarity-based high-dimensional search. It appropriately notes the convergence of these technologies (e.g., pgvector) and correctly identifies the trade-off between ACID compliance and high-throughput vector retrieval. The summary table is a high-value synthesis tool. The only minor improvement would be a brief mention of the 'curse of dimensionality' as a core technical driver for why specialized vector indices are required over standard relational B-trees. | J19: 1 | K19: 0.98 | L19: 0 | M19: 0 | N19: 0 | O19: TRUE | P19: main_001_planner_executor_reviewer | Q19: strict_v1 | R19: 18 | S19: =VLOOKUP(main_001_90runs__2[[#This Row],[prompt]],tasks!B:E,2,FALSE) -> Knowledge | T19: =VLOOKUP(main_001_90runs__2[[#This Row],[prompt]],tasks!B:E,3,FALSE) -> medium | U19: =VLOOKUP(main_001_90runs__2[[#This Row],[prompt]],tasks!B:E,4,FALSE) -> Structured comparison
A20: 1780592416686 | B20: main_001 | C20: 1 | D20: basic_agent | E20: 46177.834 | F20: Explain how memory improves long-running AI agents | G20: { "task_id": "1", "answer": "Memory improves long-running AI agents by enabling context retention, reducing redundant information processing, and facilitating iterative learning. By storing past interactions, state data, and user preferences in short-term (working) or long-term (vector database) storage, agents avoid 'amnesia' across sessions, maintain consistency in task execution, and can personalize responses over time based on historical patterns.", "execution_summary": "Defined the mechanics of memory in AI, specifically highlighting the transition from stateless processing to stateful, long-term context retention.", "confidence": 1.0 } | H20: Memory improves long-running AI agents by enabling context retention, reducing redundant information processing, and facilitating iterative learning. By storing past interactions, state data, and user preferences in short-term (working) or long-term (vector database) storage, agents avoid 'amnesia' across sessions, maintain consistency in task execution, and can personalize responses over time based on historical patterns. | I20: Defined the mechanics of memory in AI, specifically highlighting the transition from stateless processing to stateful, long-term context retention. | J20: 1 | L20: 0 | M20: 0 | N20: 0 | O20: TRUE | P20: main_001_basic_agent | R20: 19 | S20: =VLOOKUP(main_001_90runs__2[[#This Row],[prompt]],tasks!B:E,2,FALSE) -> Knowledge | T20: =VLOOKUP(main_001_90runs__2[[#This Row],[prompt]],tasks!B:E,3,FALSE) -> medium | U20: =VLOOKUP(main_001_90runs__2[[#This Row],[prompt]],tasks!B:E,4,FALSE) -> Technical explanation
A21: 1780592437302 | B21: main_001 | C21: 1 | D21: planner_executor | E21: 46177.834 | F21: Explain how memory improves long-running AI agents | G21: { "task_id": "1", "answer": "Memory in AI agents acts as a bridge between transient processing and persistent intelligence. 1) Context windows act as a 'working memory,' but they are limited by token capacity, forcing agents to lose information as interactions lengthen. 2) To overcome this, agents transition from short-term context to external persistent storage, such as vector databases (storing high-dimensional embeddings for semantic similarity) and knowledge graphs (mapping explicit relationships between entities). 3) Architecturally, agentic memory is modeled after human cognition: sensory memory (real-time stream processing), working memory (the active prompt/context window), and long-term storage (databases). 4) Retrieval-Augmented Generation (RAG) enables the agent to query these databases based on user intent, injecting relevant historical facts back into the model context. 5) This architecture enables personalized, cross-session continuity where an agent recalls user preferences, thereby reducing redundant computation and improving task relevance. 6) However, these benefits come with trade-offs: storing vast data increases operational costs and latency, and maintaining user privacy requires robust data sanitization and access control protocols.", "execution_summary": "The objective was met by defining the technical progression from ephemeral context windows to persistent storage, detailing architectural components, and evaluating the utility and trade-offs of long-term memory in agent systems.", "confidence": 1.0 } | H21: Memory in AI agents acts as a bridge between transient processing and persistent intelligence. 1) Context windows act as a 'working memory,' but they are limited by token capacity, forcing agents to lose information as interactions lengthen. 2) To overcome this, agents transition from short-term context to external persistent storage, such as vector databases (storing high-dimensional embeddings for semantic similarity) and knowledge graphs (mapping explicit relationships between entities). 3) Architecturally, agentic memory is modeled after human cognition: sensory memory (real-time stream processing), working memory (the active prompt/context window), and long-term storage (databases). 4) Retrieval-Augmented Generation (RAG) enables the agent to query these databases based on user intent, injecting relevant historical facts back into the model context. 5) This architecture enables personalized, cross-session continuity where an agent recalls user preferences, thereby reducing redundant computation and improving task relevance. 6) However, these benefits come with trade-offs: storing vast data increases operational costs and latency, and maintaining user privacy requires robust data sanitization and access control protocols. | I21: The objective was met by defining the technical progression from ephemeral context windows to persistent storage, detailing architectural components, and evaluating the utility and trade-offs of long-term memory in agent systems. | J21: 1 | L21: 0 | M21: 0 | N21: 0 | O21: TRUE | P21: main_001_planner_executor | R21: 20 | S21: =VLOOKUP(main_001_90runs__2[[#This Row],[prompt]],tasks!B:E,2,FALSE) -> Knowledge | T21: =VLOOKUP(main_001_90runs__2[[#This Row],[prompt]],tasks!B:E,3,FALSE) -> medium | U21: =VLOOKUP(main_001_90runs__2[[#This Row],[prompt]],tasks!B:E,4,FALSE) -> Technical explanation
